<?xml version="1.0"?>

<robot name="robot" >
    <material name="black">
        <color rgba="0 0 0 1"/>
    </material>
    <material name="white">
      <color rgba="1 1 1 1"/>
    </material>

    <link name="world"/>
    <joint name="fixed" type="fixed">
        <parent link="world"/>
        <child link="base_link"/>
    </joint>

    <link name= "base_link">  <!--link fixo-->  
        <collision>
            <origin xyz="0.0 0.0 1.0" rpy="0.0 0.0 0.0"/>
            <geometry>
                <box size="0.2 0.2 2.0"/>
            </geometry>
        </collision>
        <visual>
            <origin xyz="0.0 0.0 1.0" rpy="0.0 0.0 0.0"/>
            <geometry>
                <box size="0.2 0.2 2"/>
            </geometry>
            <material name="black"/>
        </visual>
        <inertial>
            <origin xyz="0.0 0.0 1.0" rpy="0.0 0.0 0.0"/>
            <mass value="2"/>
            <inertia ixx="0.67" ixy="0.0" ixz="0.0" iyy="0.67" iyz="0.0" izz="0.013"/>  <!--ixx=m(y2+z2)/12-->
        </inertial>
    </link>
    <joint name="joint1" type="continuous">
       <parent link="base_link"/>
       <child link="link2"/>
       <origin xyz="0.0 0.0 4.0" rpy="0.0 0.0 0.0"/>
       <axis xyz="0.0 1.0 0.0"/>
    </joint>

    <link name= "link2">    
        <collision>
            <origin xyz="0.0 0.0 2.0" rpy="0.0 0.0 0.0"/>
            <geometry>
                <box size="0.2 0.2 2.0"/>
            </geometry>
        </collision>
        <visual>
            <origin xyz="0.0 0.0 2.0" rpy="0.0 0.0 0.0"/>
            <geometry>
                <box size="0.2 0.2 2"/>
            </geometry>
            <material name="white"/>
        </visual>
        <inertial>
            <origin xyz="0.0 0.0 1.0" rpy="0.0 0.0 0.0"/>
            <mass value="2"/>
            <inertia ixx="0.67" ixy="0.0" ixz="0.0" iyy="0.67" iyz="0.0" izz="0.013"/>  <!--ixx=m(y2+z2)/12-->
        </inertial>
    </link>
</robot>